Workbook
Name SDGList: 'SDG List'!$A$2:$A$18

Sheet Instructions
A1: =Mapping!$C$3&" — Evaluation Workbook: How to use"
A3: Hackathon structure
A4: Round 1 | C4: 3rd Sem Section A and Section B intra-class hackathons → top 5 teams from each section shortlisted (sheets '3A Intra', '3B Intra').
A5: Round 1 | C5: 5th Sem Section A and Section B intra-class hackathons → top 5 teams from each section shortlisted (sheets '5A Intra', '5B Intra').
A6: Round 2 | C6: 3rd Sem inter-section hackathon: the 10 shortlisted teams are pulled in automatically → top 5 shortlisted (sheet '3 Inter').
A7: Round 2 | C7: 5th Sem inter-section hackathon: the 10 shortlisted teams are pulled in automatically → top 5 shortlisted (sheet '5 Inter').
A8: Who enters what
A9: Coordinator (once) | C9: 'Mapping' sheet: title, department, PO/PSO target %, attainment thresholds, SDG target strength, and (optionally) the rubric → PO/PSO correlation matrix. 'Rubric' sheet: criteria, max marks, descriptors.
A10: Coordinator (per event) | C10: In each event sheet: date, venue, evaluator names, and team details (Team ID, name, members, Primary SDG and optional Secondary SDG from the dropdown, problem statement). Intra sheets hold up to 20 teams.
A11: Evaluators | C11: In your own coloured block: the 9 rubric marks (0 to each criterion's maximum in row 6), then the contribution strength (0–3) for the team's Primary SDG and, if the team has one, its Secondary SDG. The secondary cell turns grey when there is no secondary SDG. Leave a block blank if fewer than 3 evaluators are judging.
A12: Everything else is automatic | C12: Averages across evaluators, total, %, rank, shortlist status, per-team PO/PSO attainment, event attainment levels, SDG strength and goal-wise attainment, the Dashboard and all charts.
A13: Colour legend
A14: Yellow cell, blue text | C14: Input cell — type here.
A15: Grey / lavender / green cells | C15: Calculated — do not edit (event sheets and Dashboard are protected without a password; Review ▸ Unprotect Sheet if you need to change the layout).
A16: PO / PSO attainment
A17: Criterion % | C17: Average of the evaluators' marks for a criterion ÷ its maximum marks.
A18: Team outcome attainment | C18: For each PO/PSO: Σ(criterion % × correlation) ÷ Σ correlation, using the 3/2/1 matrix on the 'Mapping' sheet.
A19: Event attainment level | C19: % of teams whose outcome attainment ≥ target (default 60%). Level 3 if ≥70% of teams, Level 2 if ≥60%, Level 1 if ≥50%, else 0 (all editable on 'Mapping').
A20: SDG attainment
A21: Contribution strength | C21: Each evaluator rates how strongly the solution advances each SDG the team claims: 3 High (advances a named target with a measurable indicator), 2 Medium (clearly supports the goal), 1 Low (indirect), 0 None (claimed only). Scale and descriptors are on the 'Rubric' sheet. Not part of the 100 marks.
A22: Solution strength | C22: Average of the evaluators' ratings for that team and SDG (0–3).
A23: Goal-wise attainment | C23: For each of the 17 SDGs: average strength of all solutions addressing it (primary or secondary), plus the % of rated solutions at or above the target strength (default 2, Medium).
A24: Event SDG attainment | C24: Average strength over every rated team–SDG pair in the event; the Dashboard pools all events weighted by the number of rated pairs.
A25: Ranking & ties | C25: Rank is by total rubric score only; SDG ratings do not change it. Ties are broken by the Technical Implementation (C4) score, then by row order. Inter-section sheets pull rank 1–5 of each section; you can overtype a team cell there if a team is replaced.
A26: Example row (format only)
A27: Section | B27: Team ID | C27: Team Name | D27: Primary SDG | E27: Evaluator 1: C1…C9 | F27: Evaluator 1: SDG strength (primary, secondary)
A28: 3rd Sem - A | B28: 3A-07 | C28: AquaSense | D28: SDG 6 - Clean Water and Sanitation | E28: 8, 7, 12, 16, 8, 7, 7, 4, 8 | F28: 3, (blank)

Sheet Dashboard
A1: =Mapping!$C$3&" — Attainment Dashboard (PO / PSO / SDG)"
A2: =Mapping!$C$4&" | Dept. of "&Mapping!$C$5&" | AY "&Mapping!$C$6&" | PO/PSO target per team: "&TEXT(Mapping!$C$7,"0%")&" | SDG reached at strength ≥ "&Mapping!$C$12
A4: Table 1 — PO / PSO average attainment (%) by event
A5: Event | B5: Teams evaluated | C5: PO1 | D5: PO2 | E5: PO3 | F5: PO4 | G5: PO5 | H5: PO6 | I5: PO7 | J5: PO8 | K5: PO9 | L5: PO10 | M5: PO11 | N5: PSO1 | O5: PSO2
A6: 3rd Sem A — Intra | B6: ='3A Intra'!E33 | C6: ='3A Intra'!BE30 | D6: ='3A Intra'!BF30 | E6: ='3A Intra'!BG30 | F6: ='3A Intra'!BH30 | G6: ='3A Intra'!BI30 | H6: ='3A Intra'!BJ30 | I6: ='3A Intra'!BK30 | J6: ='3A Intra'!BL30 | ... O6: ='3A Intra'!BQ30
A7: 3rd Sem B — Intra | B7: ='3B Intra'!E33 | C7: ='3B Intra'!BE30 | D7: ='3B Intra'!BF30 | E7: ='3B Intra'!BG30 | F7: ='3B Intra'!BH30 | G7: ='3B Intra'!BI30 | H7: ='3B Intra'!BJ30 | I7: ='3B Intra'!BK30 | J7: ='3B Intra'!BL30 | ... O7: ='3B Intra'!BQ30
A8: 3rd Sem — Inter-Section | B8: ='3 Inter'!E23 | C8: ='3 Inter'!BE20 | D8: ='3 Inter'!BF20 | E8: ='3 Inter'!BG20 | F8: ='3 Inter'!BH20 | G8: ='3 Inter'!BI20 | H8: ='3 Inter'!BJ20 | I8: ='3 Inter'!BK20 | J8: ='3 Inter'!BL20 | ... O8: ='3 Inter'!BQ20
A9: 5th Sem A — Intra | B9: ='5A Intra'!E33 | C9: ='5A Intra'!BE30 | D9: ='5A Intra'!BF30 | E9: ='5A Intra'!BG30 | F9: ='5A Intra'!BH30 | G9: ='5A Intra'!BI30 | H9: ='5A Intra'!BJ30 | I9: ='5A Intra'!BK30 | J9: ='5A Intra'!BL30 | ... O9: ='5A Intra'!BQ30
A10: 5th Sem B — Intra | B10: ='5B Intra'!E33 | C10: ='5B Intra'!BE30 | D10: ='5B Intra'!BF30 | E10: ='5B Intra'!BG30 | F10: ='5B Intra'!BH30 | G10: ='5B Intra'!BI30 | H10: ='5B Intra'!BJ30 | I10: ='5B Intra'!BK30 | J10: ='5B Intra'!BL30 | ... O10: ='5B Intra'!BQ30
A11: 5th Sem — Inter-Section | B11: ='5 Inter'!E23 | C11: ='5 Inter'!BE20 | D11: ='5 Inter'!BF20 | E11: ='5 Inter'!BG20 | F11: ='5 Inter'!BH20 | G11: ='5 Inter'!BI20 | H11: ='5 Inter'!BJ20 | I11: ='5 Inter'!BK20 | J11: ='5 Inter'!BL20 | ... O11: ='5 Inter'!BQ20
A12: Overall (weighted by teams) | B12: =SUM(B6:B11) | C12: =IFERROR(SUMPRODUCT(C6:C11,$B$6:$B$11)/SUMPRODUCT(--ISNUMBER(C6:C11),$B$6:$B$11),"") | D12: =IFERROR(SUMPRODUCT(D6:D11,$B$6:$B$11)/SUMPRODUCT(--ISNUMBER(D6:D11),$B$6:$B$11),"") | E12: =IFERROR(SUMPRODUCT(E6:E11,$B$6:$B$11)/SUMPRODUCT(--ISNUMBER(E6:E11),$B$6:$B$11),"") | F12: =IFERROR(SUMPRODUCT(F6:F11,$B$6:$B$11)/SUMPRODUCT(--ISNUMBER(F6:F11),$B$6:$B$11),"") | G12: =IFERROR(SUMPRODUCT(G6:G11,$B$6:$B$11)/SUMPRODUCT(--ISNUMBER(G6:G11),$B$6:$B$11),"") | H12: =IFERROR(SUMPRODUCT(H6:H11,$B$6:$B$11)/SUMPRODUCT(--ISNUMBER(H6:H11),$B$6:$B$11),"") | I12: =IFERROR(SUMPRODUCT(I6:I11,$B$6:$B$11)/SUMPRODUCT(--ISNUMBER(I6:I11),$B$6:$B$11),"") | J12: =IFERROR(SUMPRODUCT(J6:J11,$B$6:$B$11)/SUMPRODUCT(--ISNUMBER(J6:J11),$B$6:$B$11),"") | ... O12: =IFERROR(SUMPRODUCT(O6:O11,$B$6:$B$11)/SUMPRODUCT(--ISNUMBER(O6:O11),$B$6:$B$11),"")
A14: Table 2 — PO / PSO: % of teams at/above target by event
A15: Event | B15: Teams evaluated | C15: PO1 | D15: PO2 | E15: PO3 | F15: PO4 | G15: PO5 | H15: PO6 | I15: PO7 | J15: PO8 | K15: PO9 | L15: PO10 | M15: PO11 | N15: PSO1 | O15: PSO2
A16: 3rd Sem A — Intra | B16: ='3A Intra'!E33 | C16: ='3A Intra'!BE31 | D16: ='3A Intra'!BF31 | E16: ='3A Intra'!BG31 | F16: ='3A Intra'!BH31 | G16: ='3A Intra'!BI31 | H16: ='3A Intra'!BJ31 | I16: ='3A Intra'!BK31 | J16: ='3A Intra'!BL31 | ... O16: ='3A Intra'!BQ31
A17: 3rd Sem B — Intra | B17: ='3B Intra'!E33 | C17: ='3B Intra'!BE31 | D17: ='3B Intra'!BF31 | E17: ='3B Intra'!BG31 | F17: ='3B Intra'!BH31 | G17: ='3B Intra'!BI31 | H17: ='3B Intra'!BJ31 | I17: ='3B Intra'!BK31 | J17: ='3B Intra'!BL31 | ... O17: ='3B Intra'!BQ31
A18: 3rd Sem — Inter-Section | B18: ='3 Inter'!E23 | C18: ='3 Inter'!BE21 | D18: ='3 Inter'!BF21 | E18: ='3 Inter'!BG21 | F18: ='3 Inter'!BH21 | G18: ='3 Inter'!BI21 | H18: ='3 Inter'!BJ21 | I18: ='3 Inter'!BK21 | J18: ='3 Inter'!BL21 | ... O18: ='3 Inter'!BQ21
A19: 5th Sem A — Intra | B19: ='5A Intra'!E33 | C19: ='5A Intra'!BE31 | D19: ='5A Intra'!BF31 | E19: ='5A Intra'!BG31 | F19: ='5A Intra'!BH31 | G19: ='5A Intra'!BI31 | H19: ='5A Intra'!BJ31 | I19: ='5A Intra'!BK31 | J19: ='5A Intra'!BL31 | ... O19: ='5A Intra'!BQ31
A20: 5th Sem B — Intra | B20: ='5B Intra'!E33 | C20: ='5B Intra'!BE31 | D20: ='5B Intra'!BF31 | E20: ='5B Intra'!BG31 | F20: ='5B Intra'!BH31 | G20: ='5B Intra'!BI31 | H20: ='5B Intra'!BJ31 | I20: ='5B Intra'!BK31 | J20: ='5B Intra'!BL31 | ... O20: ='5B Intra'!BQ31
A21: 5th Sem — Inter-Section | B21: ='5 Inter'!E23 | C21: ='5 Inter'!BE21 | D21: ='5 Inter'!BF21 | E21: ='5 Inter'!BG21 | F21: ='5 Inter'!BH21 | G21: ='5 Inter'!BI21 | H21: ='5 Inter'!BJ21 | I21: ='5 Inter'!BK21 | J21: ='5 Inter'!BL21 | ... O21: ='5 Inter'!BQ21
A22: Overall (weighted by teams) | B22: =SUM(B16:B21) | C22: =IFERROR(SUMPRODUCT(C16:C21,$B$16:$B$21)/SUMPRODUCT(--ISNUMBER(C16:C21),$B$16:$B$21),"") | D22: =IFERROR(SUMPRODUCT(D16:D21,$B$16:$B$21)/SUMPRODUCT(--ISNUMBER(D16:D21),$B$16:$B$21),"") | E22: =IFERROR(SUMPRODUCT(E16:E21,$B$16:$B$21)/SUMPRODUCT(--ISNUMBER(E16:E21),$B$16:$B$21),"") | F22: =IFERROR(SUMPRODUCT(F16:F21,$B$16:$B$21)/SUMPRODUCT(--ISNUMBER(F16:F21),$B$16:$B$21),"") | G22: =IFERROR(SUMPRODUCT(G16:G21,$B$16:$B$21)/SUMPRODUCT(--ISNUMBER(G16:G21),$B$16:$B$21),"") | H22: =IFERROR(SUMPRODUCT(H16:H21,$B$16:$B$21)/SUMPRODUCT(--ISNUMBER(H16:H21),$B$16:$B$21),"") | I22: =IFERROR(SUMPRODUCT(I16:I21,$B$16:$B$21)/SUMPRODUCT(--ISNUMBER(I16:I21),$B$16:$B$21),"") | J22: =IFERROR(SUMPRODUCT(J16:J21,$B$16:$B$21)/SUMPRODUCT(--ISNUMBER(J16:J21),$B$16:$B$21),"") | ... O22: =IFERROR(SUMPRODUCT(O16:O21,$B$16:$B$21)/SUMPRODUCT(--ISNUMBER(O16:O21),$B$16:$B$21),"")
A24: Table 3 — PO / PSO attainment level (0–3) by event
A25: Event | B25: Teams evaluated | C25: PO1 | D25: PO2 | E25: PO3 | F25: PO4 | G25: PO5 | H25: PO6 | I25: PO7 | J25: PO8 | K25: PO9 | L25: PO10 | M25: PO11 | N25: PSO1 | O25: PSO2
A26: 3rd Sem A — Intra | B26: ='3A Intra'!E33 | C26: ='3A Intra'!BE32 | D26: ='3A Intra'!BF32 | E26: ='3A Intra'!BG32 | F26: ='3A Intra'!BH32 | G26: ='3A Intra'!BI32 | H26: ='3A Intra'!BJ32 | I26: ='3A Intra'!BK32 | J26: ='3A Intra'!BL32 | ... O26: ='3A Intra'!BQ32
A27: 3rd Sem B — Intra | B27: ='3B Intra'!E33 | C27: ='3B Intra'!BE32 | D27: ='3B Intra'!BF32 | E27: ='3B Intra'!BG32 | F27: ='3B Intra'!BH32 | G27: ='3B Intra'!BI32 | H27: ='3B Intra'!BJ32 | I27: ='3B Intra'!BK32 | J27: ='3B Intra'!BL32 | ... O27: ='3B Intra'!BQ32
A28: 3rd Sem — Inter-Section | B28: ='3 Inter'!E23 | C28: ='3 Inter'!BE22 | D28: ='3 Inter'!BF22 | E28: ='3 Inter'!BG22 | F28: ='3 Inter'!BH22 | G28: ='3 Inter'!BI22 | H28: ='3 Inter'!BJ22 | I28: ='3 Inter'!BK22 | J28: ='3 Inter'!BL22 | ... O28: ='3 Inter'!BQ22
A29: 5th Sem A — Intra | B29: ='5A Intra'!E33 | C29: ='5A Intra'!BE32 | D29: ='5A Intra'!BF32 | E29: ='5A Intra'!BG32 | F29: ='5A Intra'!BH32 | G29: ='5A Intra'!BI32 | H29: ='5A Intra'!BJ32 | I29: ='5A Intra'!BK32 | J29: ='5A Intra'!BL32 | ... O29: ='5A Intra'!BQ32
A30: 5th Sem B — Intra | B30: ='5B Intra'!E33 | C30: ='5B Intra'!BE32 | D30: ='5B Intra'!BF32 | E30: ='5B Intra'!BG32 | F30: ='5B Intra'!BH32 | G30: ='5B Intra'!BI32 | H30: ='5B Intra'!BJ32 | I30: ='5B Intra'!BK32 | J30: ='5B Intra'!BL32 | ... O30: ='5B Intra'!BQ32
A31: 5th Sem — Inter-Section | B31: ='5 Inter'!E23 | C31: ='5 Inter'!BE22 | D31: ='5 Inter'!BF22 | E31: ='5 Inter'!BG22 | F31: ='5 Inter'!BH22 | G31: ='5 Inter'!BI22 | H31: ='5 Inter'!BJ22 | I31: ='5 Inter'!BK22 | J31: ='5 Inter'!BL22 | ... O31: ='5 Inter'!BQ22
A32: Overall attainment level | B32: =B22 | C32: =IF(C22="","",IF(C22>=Mapping!$C$8,3,IF(C22>=Mapping!$C$9,2,IF(C22>=Mapping!$C$10,1,0)))) | D32: =IF(D22="","",IF(D22>=Mapping!$C$8,3,IF(D22>=Mapping!$C$9,2,IF(D22>=Mapping!$C$10,1,0)))) | E32: =IF(E22="","",IF(E22>=Mapping!$C$8,3,IF(E22>=Mapping!$C$9,2,IF(E22>=Mapping!$C$10,1,0)))) | F32: =IF(F22="","",IF(F22>=Mapping!$C$8,3,IF(F22>=Mapping!$C$9,2,IF(F22>=Mapping!$C$10,1,0)))) | G32: =IF(G22="","",IF(G22>=Mapping!$C$8,3,IF(G22>=Mapping!$C$9,2,IF(G22>=Mapping!$C$10,1,0)))) | H32: =IF(H22="","",IF(H22>=Mapping!$C$8,3,IF(H22>=Mapping!$C$9,2,IF(H22>=Mapping!$C$10,1,0)))) | I32: =IF(I22="","",IF(I22>=Mapping!$C$8,3,IF(I22>=Mapping!$C$9,2,IF(I22>=Mapping!$C$10,1,0)))) | J32: =IF(J22="","",IF(J22>=Mapping!$C$8,3,IF(J22>=Mapping!$C$9,2,IF(J22>=Mapping!$C$10,1,0)))) | ... O32: =IF(O22="","",IF(O22>=Mapping!$C$8,3,IF(O22>=Mapping!$C$9,2,IF(O22>=Mapping!$C$10,1,0))))
A34: Table 4 — SDG attainment by event (contribution strength, 0–3)
A35: Event | B35: Team–SDG pairs claimed | C35: Pairs rated | D35: Avg contribution strength (0–3) | E35: % rated at/above target strength
A36: 3rd Sem A — Intra | B36: ='3A Intra'!E37 | C36: ='3A Intra'!E36 | D36: ='3A Intra'!E34 | E36: ='3A Intra'!E35
A37: 3rd Sem B — Intra | B37: ='3B Intra'!E37 | C37: ='3B Intra'!E36 | D37: ='3B Intra'!E34 | E37: ='3B Intra'!E35
A38: 3rd Sem — Inter-Section | B38: ='3 Inter'!E27 | C38: ='3 Inter'!E26 | D38: ='3 Inter'!E24 | E38: ='3 Inter'!E25
A39: 5th Sem A — Intra | B39: ='5A Intra'!E37 | C39: ='5A Intra'!E36 | D39: ='5A Intra'!E34 | E39: ='5A Intra'!E35
A40: 5th Sem B — Intra | B40: ='5B Intra'!E37 | C40: ='5B Intra'!E36 | D40: ='5B Intra'!E34 | E40: ='5B Intra'!E35
A41: 5th Sem — Inter-Section | B41: ='5 Inter'!E27 | C41: ='5 Inter'!E26 | D41: ='5 Inter'!E24 | E41: ='5 Inter'!E25
A42: Overall (all rated pairs) | B42: =SUM(B36:B41) | C42: =SUM(C36:C41) | D42: =IFERROR(SUMPRODUCT(D36:D41,C36:C41)/C42,"") | E42: =IFERROR(SUMPRODUCT(E36:E41,C36:C41)/C42,"")
A45: Table 5 — SDG goal-wise attainment, all events (contribution strength, 0–3)
A46: Sustainable Development Goal | B46: 3rd Sem A — Intra: solutions | C46: 3rd Sem B — Intra: solutions | D46: 3rd Sem — Inter-Section: solutions | E46: 5th Sem A — Intra: solutions | F46: 5th Sem B — Intra: solutions | G46: 5th Sem — Inter-Section: solutions | H46: Total solutions | I46: Solutions rated | J46: Avg contribution strength (0–3) | K46: % rated at/above target strength
...

Sheet Rubric
A1: =Mapping!$C$3&" — Evaluation Rubric (for Evaluators)"
A2: Score each criterion out of its Max Marks (decimals allowed). Use the descriptors to place the team in a band, then pick a mark inside that band's range.
A3: # | B3: Criterion | C3: Short Name | D3: Max Marks | E3: Excellent (90–100%) | F3: Good (70–89%) | G3: Satisfactory (50–69%) | H3: Needs Improvement (<50%) | I3: Mark bands (auto) | J3: Mapped PO / PSO (auto, correlation)
A4: 1 | B4: Problem Identification & SDG Relevance | C4: C1 Problem & SDG | D4: 10 | E4: Real, well-scoped problem explicitly linked to specific SDG targets (e.g., 6.1, 13.1); stakeholders and measurable impact indicators identified with evidence. | F4: Relevant problem mapped to an SDG goal; scope and stakeholders mostly clear; limited supporting evidence. | G4: Problem stated in general terms; SDG link is broad or superficial; scope vague. | H4: Problem unclear or trivial; no credible SDG connection. | I4: ="E: "&IF(ROUNDUP(0.9*D4,0)>=D4,D4&"",ROUNDUP(0.9*D4,0)&"–"&D4)&CHAR(10)&"G: "&IF(ROUNDUP(0.7*D4,0)>=(ROUNDUP(0.9*D4,0)-1),(ROUNDUP(0.9*D4,0)-1)&"",ROUNDUP(0.7*D4,0)&"–"&(ROUNDUP(0.9*D4,0)-1))&CHAR(10)&"S: "&IF(ROUNDUP(0.5*D4,0)>=(ROUNDUP(0.7*D4,0)-1),(ROUNDUP(0.7*D4,0)-1)&"",ROUNDUP(0.5*D4,0)&"–"&(ROUNDUP(0.7*D4,0)-1))&CHAR(10)&"NI: "&IF(0>=(ROUNDUP(0.5*D4,0)-1),(ROUNDUP(0.5*D4,0)-1)&"",0&"–"&(ROUNDUP(0.5*D4,0)-1)) | J4: =IF(N(Mapping!D15)>0,"PO1("&Mapping!D15&") ","")&IF(N(Mapping!E15)>0,"PO2("&Mapping!E15&") ","")&IF(N(Mapping!F15)>0,"PO3("&Mapping!F15&") ","")&IF(N(Mapping!G15)>0,"PO4("&Mapping!G15&") ","")&IF(N(Mapping!H15)>0,"PO5("&Mapping!H15&") ","")&IF(N(Mapping!I15)>0,"PO6("&Mapping!I15&") ","")&IF(N(Mapping!J15)>0,"PO7("&Mapping!J15&") ","")&IF(N(Mapping!K15)>0,"PO8("&Mapping!K15&") ","")&IF(N(Mapping!L15)>0,"PO9("&Mapping!L15&") ","")&IF(N(Mapping!M15)>0,"PO10("&Mapping!M15&") ","")&IF(N(Mapping!N15)>0,"PO11("&Mapping!N15&") ","")&IF(N(Mapping!O15)>0,"PSO1("&Mapping!O15&") ","")&IF(N(Mapping!P15)>0,"PSO2("&Mapping!P15&") ","")
A5: 2 | B5: Research & Analysis of Existing Solutions | C5: C2 Research & Analysis | D5: 10 | E5: Thorough review of existing solutions, data and literature; gaps clearly articulated and used to justify the proposal. | F5: Reviews key existing solutions and identifies some gaps. | G5: Limited survey; gaps asserted without evidence. | H5: No analysis of existing work or data. | I5: ="E: "&IF(ROUNDUP(0.9*D5,0)>=D5,D5&"",ROUNDUP(0.9*D5,0)&"–"&D5)&CHAR(10)&"G: "&IF(ROUNDUP(0.7*D5,0)>=(ROUNDUP(0.9*D5,0)-1),(ROUNDUP(0.9*D5,0)-1)&"",ROUNDUP(0.7*D5,0)&"–"&(ROUNDUP(0.9*D5,0)-1))&CHAR(10)&"S: "&IF(ROUNDUP(0.5*D5,0)>=(ROUNDUP(0.7*D5,0)-1),(ROUNDUP(0.7*D5,0)-1)&"",ROUNDUP(0.5*D5,0)&"–"&(ROUNDUP(0.7*D5,0)-1))&CHAR(10)&"NI: "&IF(0>=(ROUNDUP(0.5*D5,0)-1),(ROUNDUP(0.5*D5,0)-1)&"",0&"–"&(ROUNDUP(0.5*D5,0)-1)) | J5: =IF(N(Mapping!D16)>0,"PO1("&Mapping!D16&") ","")&IF(N(Mapping!E16)>0,"PO2("&Mapping!E16&") ","")&IF(N(Mapping!F16)>0,"PO3("&Mapping!F16&") ","")&IF(N(Mapping!G16)>0,"PO4("&Mapping!G16&") ","")&IF(N(Mapping!H16)>0,"PO5("&Mapping!H16&") ","")&IF(N(Mapping!I16)>0,"PO6("&Mapping!I16&") ","")&IF(N(Mapping!J16)>0,"PO7("&Mapping!J16&") ","")&IF(N(Mapping!K16)>0,"PO8("&Mapping!K16&") ","")&IF(N(Mapping!L16)>0,"PO9("&Mapping!L16&") ","")&IF(N(Mapping!M16)>0,"PO10("&Mapping!M16&") ","")&IF(N(Mapping!N16)>0,"PO11("&Mapping!N16&") ","")&IF(N(Mapping!O16)>0,"PSO1("&Mapping!O16&") ","")&IF(N(Mapping!P16)>0,"PSO2("&Mapping!P16&") ","")
A6: 3 | B6: Solution Design & Innovation | C6: C3 Design & Innovation | D6: 15 | E6: Original, well-architected solution (architecture/flow diagrams, modules, data flow); clearly innovative beyond existing approaches. | F6: Sound design with some novelty; architecture mostly complete. | G6: Conventional design with gaps; minimal innovation. | H6: No coherent design, or a copy of an existing solution. | I6: ="E: "&IF(ROUNDUP(0.9*D6,0)>=D6,D6&"",ROUNDUP(0.9*D6,0)&"–"&D6)&CHAR(10)&"G: "&IF(ROUNDUP(0.7*D6,0)>=(ROUNDUP(0.9*D6,0)-1),(ROUNDUP(0.9*D6,0)-1)&"",ROUNDUP(0.7*D6,0)&"–"&(ROUNDUP(0.9*D6,0)-1))&CHAR(10)&"S: "&IF(ROUNDUP(0.5*D6,0)>=(ROUNDUP(0.7*D6,0)-1),(ROUNDUP(0.7*D6,0)-1)&"",ROUNDUP(0.5*D6,0)&"–"&(ROUNDUP(0.7*D6,0)-1))&CHAR(10)&"NI: "&IF(0>=(ROUNDUP(0.5*D6,0)-1),(ROUNDUP(0.5*D6,0)-1)&"",0&"–"&(ROUNDUP(0.5*D6,0)-1)) | J6: =IF(N(Mapping!D17)>0,"PO1("&Mapping!D17&") ","")&IF(N(Mapping!E17)>0,"PO2("&Mapping!E17&") ","")&IF(N(Mapping!F17)>0,"PO3("&Mapping!F17&") ","")&IF(N(Mapping!G17)>0,"PO4("&Mapping!G17&") ","")&IF(N(Mapping!H17)>0,"PO5("&Mapping!H17&") ","")&IF(N(Mapping!I17)>0,"PO6("&Mapping!I17&") ","")&IF(N(Mapping!J17)>0,"PO7("&Mapping!J17&") ","")&IF(N(Mapping!K17)>0,"PO8("&Mapping!K17&") ","")&IF(N(Mapping!L17)>0,"PO9("&Mapping!L17&") ","")&IF(N(Mapping!M17)>0,"PO10("&Mapping!M17&") ","")&IF(N(Mapping!N17)>0,"PO11("&Mapping!N17&") ","")&IF(N(Mapping!O17)>0,"PSO1("&Mapping!O17&") ","")&IF(N(Mapping!P17)>0,"PSO2("&Mapping!P17&") ","")
A7: 4 | B7: Technical Implementation & Tool Usage | C7: C4 Implementation | D7: 20 | E7: Working prototype demonstrates core features end-to-end; modern tools/frameworks used effectively; clean, version-controlled code. | F7: Prototype works for most core features; appropriate tools used. | G7: Partial prototype or mock-up with limited functionality. | H7: No working implementation. | I7: ="E: "&IF(ROUNDUP(0.9*D7,0)>=D7,D7&"",ROUNDUP(0.9*D7,0)&"–"&D7)&CHAR(10)&"G: "&IF(ROUNDUP(0.7*D7,0)>=(ROUNDUP(0.9*D7,0)-1),(ROUNDUP(0.9*D7,0)-1)&"",ROUNDUP(0.7*D7,0)&"–"&(ROUNDUP(0.9*D7,0)-1))&CHAR(10)&"S: "&IF(ROUNDUP(0.5*D7,0)>=(ROUNDUP(0.7*D7,0)-1),(ROUNDUP(0.7*D7,0)-1)&"",ROUNDUP(0.5*D7,0)&"–"&(ROUNDUP(0.7*D7,0)-1))&CHAR(10)&"NI: "&IF(0>=(ROUNDUP(0.5*D7,0)-1),(ROUNDUP(0.5*D7,0)-1)&"",0&"–"&(ROUNDUP(0.5*D7,0)-1)) | J7: =IF(N(Mapping!D18)>0,"PO1("&Mapping!D18&") ","")&IF(N(Mapping!E18)>0,"PO2("&Mapping!E18&") ","")&IF(N(Mapping!F18)>0,"PO3("&Mapping!F18&") ","")&IF(N(Mapping!G18)>0,"PO4("&Mapping!G18&") ","")&IF(N(Mapping!H18)>0,"PO5("&Mapping!H18&") ","")&IF(N(Mapping!I18)>0,"PO6("&Mapping!I18&") ","")&IF(N(Mapping!J18)>0,"PO7("&Mapping!J18&") ","")&IF(N(Mapping!K18)>0,"PO8("&Mapping!K18&") ","")&IF(N(Mapping!L18)>0,"PO9("&Mapping!L18&") ","")&IF(N(Mapping!M18)>0,"PO10("&Mapping!M18&") ","")&IF(N(Mapping!N18)>0,"PO11("&Mapping!N18&") ","")&IF(N(Mapping!O18)>0,"PSO1("&Mapping!O18&") ","")&IF(N(Mapping!P18)>0,"PSO2("&Mapping!P18&") ","")
A8: 5 | B8: Intelligent & Smart System Features (AI/ML, IoT, Analytics) | C8: C5 Intelligent Features | D8: 10 | E8: Meaningful use of AI/ML, data analytics, IoT or automation with justified technology/model choice and measured performance. | F8: Intelligent component present and working; limited evaluation. | G8: Intelligent feature only proposed or rudimentary (hard-coded rules). | H8: No intelligent or data-driven element. | I8: ="E: "&IF(ROUNDUP(0.9*D8,0)>=D8,D8&"",ROUNDUP(0.9*D8,0)&"–"&D8)&CHAR(10)&"G: "&IF(ROUNDUP(0.7*D8,0)>=(ROUNDUP(0.9*D8,0)-1),(ROUNDUP(0.9*D8,0)-1)&"",ROUNDUP(0.7*D8,0)&"–"&(ROUNDUP(0.9*D8,0)-1))&CHAR(10)&"S: "&IF(ROUNDUP(0.5*D8,0)>=(ROUNDUP(0.7*D8,0)-1),(ROUNDUP(0.7*D8,0)-1)&"",ROUNDUP(0.5*D8,0)&"–"&(ROUNDUP(0.7*D8,0)-1))&CHAR(10)&"NI: "&IF(0>=(ROUNDUP(0.5*D8,0)-1),(ROUNDUP(0.5*D8,0)-1)&"",0&"–"&(ROUNDUP(0.5*D8,0)-1)) | J8: =IF(N(Mapping!D19)>0,"PO1("&Mapping!D19&") ","")&IF(N(Mapping!E19)>0,"PO2("&Mapping!E19&") ","")&IF(N(Mapping!F19)>0,"PO3("&Mapping!F19&") ","")&IF(N(Mapping!G19)>0,"PO4("&Mapping!G19&") ","")&IF(N(Mapping!H19)>0,"PO5("&Mapping!H19&") ","")&IF(N(Mapping!I19)>0,"PO6("&Mapping!I19&") ","")&IF(N(Mapping!J19)>0,"PO7("&Mapping!J19&") ","")&IF(N(Mapping!K19)>0,"PO8("&Mapping!K19&") ","")&IF(N(Mapping!L19)>0,"PO9("&Mapping!L19&") ","")&IF(N(Mapping!M19)>0,"PO10("&Mapping!M19&") ","")&IF(N(Mapping!N19)>0,"PO11("&Mapping!N19&") ","")&IF(N(Mapping!O19)>0,"PSO1("&Mapping!O19&") ","")&IF(N(Mapping!P19)>0,"PSO2("&Mapping!P19&") ","")
A9: 6 | B9: Sustainability, Societal Impact & Ethics | C9: C6 Impact & Ethics | D9: 10 | E9: Quantified social/environmental impact; addresses privacy, safety, inclusivity, bias and environmental footprint. | F9: Impact and ethical aspects discussed with some specifics. | G9: Impact claimed in general terms; ethics mentioned only briefly. | H9: Impact and ethical considerations ignored. | I9: ="E: "&IF(ROUNDUP(0.9*D9,0)>=D9,D9&"",ROUNDUP(0.9*D9,0)&"–"&D9)&CHAR(10)&"G: "&IF(ROUNDUP(0.7*D9,0)>=(ROUNDUP(0.9*D9,0)-1),(ROUNDUP(0.9*D9,0)-1)&"",ROUNDUP(0.7*D9,0)&"–"&(ROUNDUP(0.9*D9,0)-1))&CHAR(10)&"S: "&IF(ROUNDUP(0.5*D9,0)>=(ROUNDUP(0.7*D9,0)-1),(ROUNDUP(0.7*D9,0)-1)&"",ROUNDUP(0.5*D9,0)&"–"&(ROUNDUP(0.7*D9,0)-1))&CHAR(10)&"NI: "&IF(0>=(ROUNDUP(0.5*D9,0)-1),(ROUNDUP(0.5*D9,0)-1)&"",0&"–"&(ROUNDUP(0.5*D9,0)-1)) | J9: =IF(N(Mapping!D20)>0,"PO1("&Mapping!D20&") ","")&IF(N(Mapping!E20)>0,"PO2("&Mapping!E20&") ","")&IF(N(Mapping!F20)>0,"PO3("&Mapping!F20&") ","")&IF(N(Mapping!G20)>0,"PO4("&Mapping!G20&") ","")&IF(N(Mapping!H20)>0,"PO5("&Mapping!H20&") ","")&IF(N(Mapping!I20)>0,"PO6("&Mapping!I20&") ","")&IF(N(Mapping!J20)>0,"PO7("&Mapping!J20&") ","")&IF(N(Mapping!K20)>0,"PO8("&Mapping!K20&") ","")&IF(N(Mapping!L20)>0,"PO9("&Mapping!L20&") ","")&IF(N(Mapping!M20)>0,"PO10("&Mapping!M20&") ","")&IF(N(Mapping!N20)>0,"PO11("&Mapping!N20&") ","")&IF(N(Mapping!O20)>0,"PSO1("&Mapping!O20&") ","")&IF(N(Mapping!P20)>0,"PSO2("&Mapping!P20&") ","")
A10: 7 | B10: Feasibility, Scalability & Cost | C10: C7 Feasibility & Cost | D10: 10 | E10: Realistic deployment plan, cost estimate or business model, scalability path and risks identified. | F10: Feasible, with rough costing and some scalability considerations. | G10: Feasibility asserted; costing or scaling not addressed. | H10: Infeasible, or no deployment thinking. | I10: ="E: "&IF(ROUNDUP(0.9*D10,0)>=D10,D10&"",ROUNDUP(0.9*D10,0)&"–"&D10)&CHAR(10)&"G: "&IF(ROUNDUP(0.7*D10,0)>=(ROUNDUP(0.9*D10,0)-1),(ROUNDUP(0.9*D10,0)-1)&"",ROUNDUP(0.7*D10,0)&"–"&(ROUNDUP(0.9*D10,0)-1))&CHAR(10)&"S: "&IF(ROUNDUP(0.5*D10,0)>=(ROUNDUP(0.7*D10,0)-1),(ROUNDUP(0.7*D10,0)-1)&"",ROUNDUP(0.5*D10,0)&"–"&(ROUNDUP(0.7*D10,0)-1))&CHAR(10)&"NI: "&IF(0>=(ROUNDUP(0.5*D10,0)-1),(ROUNDUP(0.5*D10,0)-1)&"",0&"–"&(ROUNDUP(0.5*D10,0)-1)) | J10: =IF(N(Mapping!D21)>0,"PO1("&Mapping!D21&") ","")&IF(N(Mapping!E21)>0,"PO2("&Mapping!E21&") ","")&IF(N(Mapping!F21)>0,"PO3("&Mapping!F21&") ","")&IF(N(Mapping!G21)>0,"PO4("&Mapping!G21&") ","")&IF(N(Mapping!H21)>0,"PO5("&Mapping!H21&") ","")&IF(N(Mapping!I21)>0,"PO6("&Mapping!I21&") ","")&IF(N(Mapping!J21)>0,"PO7("&Mapping!J21&") ","")&IF(N(Mapping!K21)>0,"PO8("&Mapping!K21&") ","")&IF(N(Mapping!L21)>0,"PO9("&Mapping!L21&") ","")&IF(N(Mapping!M21)>0,"PO10("&Mapping!M21&") ","")&IF(N(Mapping!N21)>0,"PO11("&Mapping!N21&") ","")&IF(N(Mapping!O21)>0,"PSO1("&Mapping!O21&") ","")&IF(N(Mapping!P21)>0,"PSO2("&Mapping!P21&") ","")
A11: 8 | B11: Teamwork & Project Management | C11: C8 Teamwork | D11: 5 | E11: Clear roles and balanced contribution; planned timeline/task tracking evident; every member answers confidently. | F11: Roles defined; most members contribute. | G11: Uneven contribution; little evidence of planning. | H11: One or two members did most of the work; no planning. | I11: ="E: "&IF(ROUNDUP(0.9*D11,0)>=D11,D11&"",ROUNDUP(0.9*D11,0)&"–"&D11)&CHAR(10)&"G: "&IF(ROUNDUP(0.7*D11,0)>=(ROUNDUP(0.9*D11,0)-1),(ROUNDUP(0.9*D11,0)-1)&"",ROUNDUP(0.7*D11,0)&"–"&(ROUNDUP(0.9*D11,0)-1))&CHAR(10)&"S: "&IF(ROUNDUP(0.5*D11,0)>=(ROUNDUP(0.7*D11,0)-1),(ROUNDUP(0.7*D11,0)-1)&"",ROUNDUP(0.5*D11,0)&"–"&(ROUNDUP(0.7*D11,0)-1))&CHAR(10)&"NI: "&IF(0>=(ROUNDUP(0.5*D11,0)-1),(ROUNDUP(0.5*D11,0)-1)&"",0&"–"&(ROUNDUP(0.5*D11,0)-1)) | J11: =IF(N(Mapping!D22)>0,"PO1("&Mapping!D22&") ","")&IF(N(Mapping!E22)>0,"PO2("&Mapping!E22&") ","")&IF(N(Mapping!F22)>0,"PO3("&Mapping!F22&") ","")&IF(N(Mapping!G22)>0,"PO4("&Mapping!G22&") ","")&IF(N(Mapping!H22)>0,"PO5("&Mapping!H22&") ","")&IF(N(Mapping!I22)>0,"PO6("&Mapping!I22&") ","")&IF(N(Mapping!J22)>0,"PO7("&Mapping!J22&") ","")&IF(N(Mapping!K22)>0,"PO8("&Mapping!K22&") ","")&IF(N(Mapping!L22)>0,"PO9("&Mapping!L22&") ","")&IF(N(Mapping!M22)>0,"PO10("&Mapping!M22&") ","")&IF(N(Mapping!N22)>0,"PO11("&Mapping!N22&") ","")&IF(N(Mapping!O22)>0,"PSO1("&Mapping!O22&") ","")&IF(N(Mapping!P22)>0,"PSO2("&Mapping!P22&") ","")
A12: 9 | B12: Presentation, Demo & Q&A | C12: C9 Presentation & Q&A | D12: 10 | E12: Clear, time-bound pitch; compelling live demo; accurate, confident answers to technical questions. | F12: Clear presentation and demo; answers most questions. | G12: Presentation unclear or over time; weak answers. | H12: Disorganised; unable to answer questions. | I12: ="E: "&IF(ROUNDUP(0.9*D12,0)>=D12,D12&"",ROUNDUP(0.9*D12,0)&"–"&D12)&CHAR(10)&"G: "&IF(ROUNDUP(0.7*D12,0)>=(ROUNDUP(0.9*D12,0)-1),(ROUNDUP(0.9*D12,0)-1)&"",ROUNDUP(0.7*D12,0)&"–"&(ROUNDUP(0.9*D12,0)-1))&CHAR(10)&"S: "&IF(ROUNDUP(0.5*D12,0)>=(ROUNDUP(0.7*D12,0)-1),(ROUNDUP(0.7*D12,0)-1)&"",ROUNDUP(0.5*D12,0)&"–"&(ROUNDUP(0.7*D12,0)-1))&CHAR(10)&"NI: "&IF(0>=(ROUNDUP(0.5*D12,0)-1),(ROUNDUP(0.5*D12,0)-1)&"",0&"–"&(ROUNDUP(0.5*D12,0)-1)) | J12: =IF(N(Mapping!D23)>0,"PO1("&Mapping!D23&") ","")&IF(N(Mapping!E23)>0,"PO2("&Mapping!E23&") ","")&IF(N(Mapping!F23)>0,"PO3("&Mapping!F23&") ","")&IF(N(Mapping!G23)>0,"PO4("&Mapping!G23&") ","")&IF(N(Mapping!H23)>0,"PO5("&Mapping!H23&") ","")&IF(N(Mapping!I23)>0,"PO6("&Mapping!I23&") ","")&IF(N(Mapping!J23)>0,"PO7("&Mapping!J23&") ","")&IF(N(Mapping!K23)>0,"PO8("&Mapping!K23&") ","")&IF(N(Mapping!L23)>0,"PO9("&Mapping!L23&") ","")&IF(N(Mapping!M23)>0,"PO10("&Mapping!M23&") ","")&IF(N(Mapping!N23)>0,"PO11("&Mapping!N23&") ","")&IF(N(Mapping!O23)>0,"PSO1("&Mapping!O23&") ","")&IF(N(Mapping!P23)>0,"PSO2("&Mapping!P23&") ","")
C13: Total | D13: =SUM(D4:D12)
A16: SDG contribution strength — rate each SDG the team claims (primary and secondary) separately. Not part of the 100 marks.
A17: Rating | B17: Strength | C17: What the evaluator should see
A18: 3 | B18: High | C18: Directly advances a named SDG target (e.g. 6.1), with a measurable indicator and a working solution that plausibly moves it.
A19: 2 | B19: Medium | C19: Meaningfully supports the goal. The goal is clearly served, but the impact is described qualitatively or the target is only broadly named.
A20: 1 | B20: Low | C20: Indirect or enabling. The solution helps something else that in turn helps the goal, such as general awareness.
A21: 0 | B21: None | C21: Claimed but not shown. The SDG label does not match what the solution actually does.
A22: Rate the solution's contribution to that goal, not the overall quality of the project. Solution strength = average across evaluators; goal attainment = average over all solutions addressing the goal.

Sheet Mapping
A1: Settings & Rubric → PO / PSO Mapping Matrix
A3: Hackathon title | C3: SDG Hackathon 2026 | H3: Yellow cells are editable. Correlation strength: 3 = High, 2 = Medium, 1 = Low, blank/0 = not mapped.
A4: Institution | C4: Canara Engineering College, Mangaluru
A5: Department | C5: Artificial Intelligence and Machine Learning | H5: Attainment method: each team's outcome attainment = Σ(criterion score ÷ criterion max × correlation) ÷ Σ correlation. Event attainment level is set by the % of teams reaching the target score for that outcome. SDGs are not mapped here: evaluators rate each claimed SDG 0–3 on the event sheets and SDG attainment is the average strength.
A6: Academic year | C6: 2026-27
A7: Target score per team (% of maximum marks) | C7: 0.6
A8: Attainment Level 3 if % of teams at/above target ≥ | C8: 0.7
A9: Attainment Level 2 if % of teams at/above target ≥ | C9: 0.6
A10: Attainment Level 1 if % of teams at/above target ≥ | C10: 0.5
A11: Teams shortlisted per round (fixed at 5 by event format) | C11: 5
A12: SDG contribution counts as reached at strength ≥ (1–3) | C12: 2
A14: # | B14: Rubric Criterion | C14: Max Marks | D14: PO1 | E14: PO2 | F14: PO3 | G14: PO4 | H14: PO5 | I14: PO6 | J14: PO7 | K14: PO8 | L14: PO9 | M14: PO10 | N14: PO11 | O14: PSO1 | P14: PSO2
A15: 1 | B15: =Rubric!B4 | C15: =Rubric!D4 | D15: 1 | E15: 3 | G15: 1 | I15: 3 | N15: 1 | P15: 1
A16: 2 | B16: =Rubric!B5 | C16: =Rubric!D5 | D16: 2 | E16: 3 | G16: 3 | H16: 1 | I16: 1 | N16: 2
A17: 3 | B17: =Rubric!B6 | C17: =Rubric!D6 | D17: 2 | E17: 2 | F17: 3 | G17: 1 | I17: 1 | O17: 2 | P17: 3
A18: 4 | B18: =Rubric!B7 | C18: =Rubric!D7 | D18: 2 | F18: 2 | H18: 3 | K18: 1 | N18: 1 | O18: 3 | P18: 2
A19: 5 | B19: =Rubric!B8 | C19: =Rubric!D8 | D19: 2 | E19: 1 | F19: 1 | G19: 2 | H19: 2 | N19: 1 | O19: 3 | P19: 1
A20: 6 | B20: =Rubric!B9 | C20: =Rubric!D9 | F20: 1 | I20: 3 | J20: 3 | P20: 1
A21: 7 | B21: =Rubric!B10 | C21: =Rubric!D10 | F21: 1 | I21: 2 | M21: 3 | P21: 2
A22: 8 | B22: =Rubric!B11 | C22: =Rubric!D11 | J22: 1 | K22: 3 | L22: 1 | M22: 2
A23: 9 | B23: =Rubric!B12 | C23: =Rubric!D12 | K23: 2 | L23: 3 | N23: 1 | P23: 1
B24: Σ Correlation | D24: =SUM(D15:D23) | E24: =SUM(E15:E23) | F24: =SUM(F15:F23) | G24: =SUM(G15:G23) | H24: =SUM(H15:H23) | I24: =SUM(I15:I23) | J24: =SUM(J15:J23) | K24: =SUM(K15:K23) | ... P24: =SUM(P15:P23)
B25: No. of criteria mapped | D25: =COUNTIF(D15:D23,">0") | E25: =COUNTIF(E15:E23,">0") | F25: =COUNTIF(F15:F23,">0") | G25: =COUNTIF(G15:G23,">0") | H25: =COUNTIF(H15:H23,">0") | I25: =COUNTIF(I15:I23,">0") | J25: =COUNTIF(J15:J23,">0") | K25: =COUNTIF(K15:K23,">0") | ... P25: =COUNTIF(P15:P23,">0")
A27: Programme Outcomes and Programme Specific Outcomes
A28: PO1 | B28: Engineering Knowledge
A29: PO2 | B29: Problem Analysis
A30: PO3 | B30: Design/Development of Solutions
A31: PO4 | B31: Conduct Investigations of Complex Problems
A32: PO5 | B32: Engineering Tool Usage
A33: PO6 | B33: The Engineer and The World
A34: PO7 | B34: Ethics
A35: PO8 | B35: Individual and Collaborative Team Work
A36: PO9 | B36: Communication
A37: PO10 | B37: Project Management and Finance
A38: PO11 | B38: Life-Long Learning
A39: PSO1 | B39: Intelligent Systems: Select appropriate technologies to analyse, design, implement, and deployment of smart and intelligent systems
A40: PSO2 | B40: Contemporary Systems: Design, and development of efficient IT solutions for challenging issues through experiential learning

Sheet 3A Intra
A1: =Mapping!$C$3&" — 3rd Semester Section A — Intra-Class Hackathon" | AP1: =Mapping!$C$4&" | Dept. of "&Mapping!$C$5&" | AY "&Mapping!$C$6
A2: Date: | D2: Venue / Coordinator: | AP2: ="PO/PSO target per team: "&TEXT(Mapping!$C$7,"0%")&" | SDG reached at strength ≥ "&Mapping!$C$12&" | Shortlist: top "&Mapping!$C$11
D3: Evaluator names → | I3: Evaluator 1: | T3: Evaluator 2: | AE3: Evaluator 3:
A4: Team Details (Coordinator) | I4: Evaluator 1 — rubric marks, then SDG contribution strength (0–3) | T4: Evaluator 2 — rubric marks, then SDG contribution strength (0–3) | AE4: Evaluator 3 — rubric marks, then SDG contribution strength (0–3) | AP4: Consolidated rubric score (average of evaluators) | AY4: SDG strength (avg, 0–3) | BA4: Result | BE4: Programme Outcome attainment per team (%) | BP4: PSO attainment (%)
A5: S.No | B5: Section | C5: Team ID | D5: Team Name | E5: Team Members (USN / Name) | F5: Primary SDG | G5: Secondary SDG (optional) | H5: Problem Statement / Project Title | I5: =Rubric!C4 | J5: =Rubric!C5 | K5: =Rubric!C6 | L5: =Rubric!C7 | M5: =Rubric!C8 | N5: =Rubric!C9 | O5: =Rubric!C10 | P5: =Rubric!C11 | Q5: =Rubric!C12 | R5: Primary SDG strength | S5: Secondary SDG strength | T5: =Rubric!C4 | U5: =Rubric!C5 | V5: =Rubric!C6 | W5: =Rubric!C7 | X5: =Rubric!C8 | Y5: =Rubric!C9 | Z5: =Rubric!C10 | AA5: =Rubric!C11 | AB5: =Rubric!C12 | AC5: Primary SDG strength | AD5: Secondary SDG strength | AE5: =Rubric!C4 | AF5: =Rubric!C5 | AG5: =Rubric!C6 | AH5: =Rubric!C7 | AI5: =Rubric!C8 | AJ5: =Rubric!C9 | AK5: =Rubric!C10 | AL5: =Rubric!C11 | AM5: =Rubric!C12 | AN5: Primary SDG strength | AO5: Secondary SDG strength | AP5: =Rubric!C4 | AQ5: =Rubric!C5 | AR5: =Rubric!C6 | AS5: =Rubric!C7 | AT5: =Rubric!C8 | AU5: =Rubric!C9 | AV5: =Rubric!C10 | AW5: =Rubric!C11 | AX5: =Rubric!C12 | AY5: Primary SDG strength | AZ5: Secondary SDG strength | BA5: Total | BB5: Score % | BC5: Rank | BD5: Status | BE5: PO1 | BF5: PO2 | BG5: PO3 | BH5: PO4 | BI5: PO5 | BJ5: PO6 | BK5: PO7 | BL5: PO8 | BM5: PO9 | BN5: PO10 | BO5: PO11 | BP5: PSO1 | BQ5: PSO2
I6: =Rubric!D4 | J6: =Rubric!D5 | K6: =Rubric!D6 | L6: =Rubric!D7 | M6: =Rubric!D8 | N6: =Rubric!D9 | O6: =Rubric!D10 | P6: =Rubric!D11 | Q6: =Rubric!D12 | R6: 0–3 | S6: 0–3 | T6: =Rubric!D4 | U6: =Rubric!D5 | V6: =Rubric!D6 | W6: =Rubric!D7 | X6: =Rubric!D8 | Y6: =Rubric!D9 | Z6: =Rubric!D10 | AA6: =Rubric!D11 | AB6: =Rubric!D12 | AC6: 0–3 | AD6: 0–3 | AE6: =Rubric!D4 | AF6: =Rubric!D5 | AG6: =Rubric!D6 | AH6: =Rubric!D7 | AI6: =Rubric!D8 | AJ6: =Rubric!D9 | AK6: =Rubric!D10 | AL6: =Rubric!D11 | AM6: =Rubric!D12 | AN6: 0–3 | AO6: 0–3 | AP6: =Rubric!D4 | AQ6: =Rubric!D5 | AR6: =Rubric!D6 | AS6: =Rubric!D7 | AT6: =Rubric!D8 | AU6: =Rubric!D9 | AV6: =Rubric!D10 | AW6: =Rubric!D11 | AX6: =Rubric!D12 | AY6: 0–3 | AZ6: 0–3 | BA6: =Rubric!$D$13 | BE6: % | BF6: % | BG6: % | BH6: % | BI6: % | BJ6: % | BK6: % | BL6: % | BM6: % | BN6: % | BO6: % | BP6: % | BQ6: %
A7: 1 | B7: 3rd Sem - A | AP7: =IF(COUNT(I7,T7,AE7)=0,"",AVERAGE(I7,T7,AE7)) | AQ7: =IF(COUNT(J7,U7,AF7)=0,"",AVERAGE(J7,U7,AF7)) | AR7: =IF(COUNT(K7,V7,AG7)=0,"",AVERAGE(K7,V7,AG7)) | AS7: =IF(COUNT(L7,W7,AH7)=0,"",AVERAGE(L7,W7,AH7)) | AT7: =IF(COUNT(M7,X7,AI7)=0,"",AVERAGE(M7,X7,AI7)) | AU7: =IF(COUNT(N7,Y7,AJ7)=0,"",AVERAGE(N7,Y7,AJ7)) | AV7: =IF(COUNT(O7,Z7,AK7)=0,"",AVERAGE(O7,Z7,AK7)) | AW7: =IF(COUNT(P7,AA7,AL7)=0,"",AVERAGE(P7,AA7,AL7)) | AX7: =IF(COUNT(Q7,AB7,AM7)=0,"",AVERAGE(Q7,AB7,AM7)) | AY7: =IF(OR($F7="",COUNT(R7,AC7,AN7)=0),"",AVERAGE(R7,AC7,AN7)) | AZ7: =IF(OR($G7="",$G7=$F7,COUNT(S7,AD7,AO7)=0),"",AVERAGE(S7,AD7,AO7)) | BA7: =IF(COUNT(AP7:AX7)=0,"",SUM(AP7:AX7)) | BB7: =IF(BA7="","",BA7/BA$6) | BC7: =IF(BR7="","",COUNTIF($BR$7:$BR$26,">"&BR7)+COUNTIF($BR$7:BR7,BR7)) | BD7: =IF(BC7="","",IF(BC7<=Mapping!$C$11,"Shortlisted","Not shortlisted")) | BE7: =IFERROR((AP7/AP$6*Mapping!$D$15+AQ7/AQ$6*Mapping!$D$16+AR7/AR$6*Mapping!$D$17+AS7/AS$6*Mapping!$D$18+AT7/AT$6*Mapping!$D$19+AU7/AU$6*Mapping!$D$20+AV7/AV$6*Mapping!$D$21+AW7/AW$6*Mapping!$D$22+AX7/AX$6*Mapping!$D$23)/SUM(Mapping!$D$15:$D$23),"") | BF7: =IFERROR((AP7/AP$6*Mapping!$E$15+AQ7/AQ$6*Mapping!$E$16+AR7/AR$6*Mapping!$E$17+AS7/AS$6*Mapping!$E$18+AT7/AT$6*Mapping!$E$19+AU7/AU$6*Mapping!$E$20+AV7/AV$6*Mapping!$E$21+AW7/AW$6*Mapping!$E$22+AX7/AX$6*Mapping!$E$23)/SUM(Mapping!$E$15:$E$23),"") | BG7: =IFERROR((AP7/AP$6*Mapping!$F$15+AQ7/AQ$6*Mapping!$F$16+AR7/AR$6*Mapping!$F$17+AS7/AS$6*Mapping!$F$18+AT7/AT$6*Mapping!$F$19+AU7/AU$6*Mapping!$F$20+AV7/AV$6*Mapping!$F$21+AW7/AW$6*Mapping!$F$22+AX7/AX$6*Mapping!$F$23)/SUM(Mapping!$F$15:$F$23),"") | BH7: =IFERROR((AP7/AP$6*Mapping!$G$15+AQ7/AQ$6*Mapping!$G$16+AR7/AR$6*Mapping!$G$17+AS7/AS$6*Mapping!$G$18+AT7/AT$6*Mapping!$G$19+AU7/AU$6*Mapping!$G$20+AV7/AV$6*Mapping!$G$21+AW7/AW$6*Mapping!$G$22+AX7/AX$6*Mapping!$G$23)/SUM(Mapping!$G$15:$G$23),"") | BI7: =IFERROR((AP7/AP$6*Mapping!$H$15+AQ7/AQ$6*Mapping!$H$16+AR7/AR$6*Mapping!$H$17+AS7/AS$6*Mapping!$H$18+AT7/AT$6*Mapping!$H$19+AU7/AU$6*Mapping!$H$20+AV7/AV$6*Mapping!$H$21+AW7/AW$6*Mapping!$H$22+AX7/AX$6*Mapping!$H$23)/SUM(Mapping!$H$15:$H$23),"") | BJ7: =IFERROR((AP7/AP$6*Mapping!$I$15+AQ7/AQ$6*Mapping!$I$16+AR7/AR$6*Mapping!$I$17+AS7/AS$6*Mapping!$I$18+AT7/AT$6*Mapping!$I$19+AU7/AU$6*Mapping!$I$20+AV7/AV$6*Mapping!$I$21+AW7/AW$6*Mapping!$I$22+AX7/AX$6*Mapping!$I$23)/SUM(Mapping!$I$15:$I$23),"") | BK7: =IFERROR((AP7/AP$6*Mapping!$J$15+AQ7/AQ$6*Mapping!$J$16+AR7/AR$6*Mapping!$J$17+AS7/AS$6*Mapping!$J$18+AT7/AT$6*Mapping!$J$19+AU7/AU$6*Mapping!$J$20+AV7/AV$6*Mapping!$J$21+AW7/AW$6*Mapping!$J$22+AX7/AX$6*Mapping!$J$23)/SUM(Mapping!$J$15:$J$23),"") | BL7: =IFERROR((AP7/AP$6*Mapping!$K$15+AQ7/AQ$6*Mapping!$K$16+AR7/AR$6*Mapping!$K$17+AS7/AS$6*Mapping!$K$18+AT7/AT$6*Mapping!$K$19+AU7/AU$6*Mapping!$K$20+AV7/AV$6*Mapping!$K$21+AW7/AW$6*Mapping!$K$22+AX7/AX$6*Mapping!$K$23)/SUM(Mapping!$K$15:$K$23),"") | BM7: =IFERROR((AP7/AP$6*Mapping!$L$15+AQ7/AQ$6*Mapping!$L$16+AR7/AR$6*Mapping!$L$17+AS7/AS$6*Mapping!$L$18+AT7/AT$6*Mapping!$L$19+AU7/AU$6*Mapping!$L$20+AV7/AV$6*Mapping!$L$21+AW7/AW$6*Mapping!$L$22+AX7/AX$6*Mapping!$L$23)/SUM(Mapping!$L$15:$L$23),"") | BN7: =IFERROR((AP7/AP$6*Mapping!$M$15+AQ7/AQ$6*Mapping!$M$16+AR7/AR$6*Mapping!$M$17+AS7/AS$6*Mapping!$M$18+AT7/AT$6*Mapping!$M$19+AU7/AU$6*Mapping!$M$20+AV7/AV$6*Mapping!$M$21+AW7/AW$6*Mapping!$M$22+AX7/AX$6*Mapping!$M$23)/SUM(Mapping!$M$15:$M$23),"") | BO7: =IFERROR((AP7/AP$6*Mapping!$N$15+AQ7/AQ$6*Mapping!$N$16+AR7/AR$6*Mapping!$N$17+AS7/AS$6*Mapping!$N$18+AT7/AT$6*Mapping!$N$19+AU7/AU$6*Mapping!$N$20+AV7/AV$6*Mapping!$N$21+AW7/AW$6*Mapping!$N$22+AX7/AX$6*Mapping!$N$23)/SUM(Mapping!$N$15:$N$23),"") | BP7: =IFERROR((AP7/AP$6*Mapping!$O$15+AQ7/AQ$6*Mapping!$O$16+AR7/AR$6*Mapping!$O$17+AS7/AS$6*Mapping!$O$18+AT7/AT$6*Mapping!$O$19+AU7/AU$6*Mapping!$O$20+AV7/AV$6*Mapping!$O$21+AW7/AW$6*Mapping!$O$22+AX7/AX$6*Mapping!$O$23)/SUM(Mapping!$O$15:$O$23),"") | BQ7: =IFERROR((AP7/AP$6*Mapping!$P$15+AQ7/AQ$6*Mapping!$P$16+AR7/AR$6*Mapping!$P$17+AS7/AS$6*Mapping!$P$18+AT7/AT$6*Mapping!$P$19+AU7/AU$6*Mapping!$P$20+AV7/AV$6*Mapping!$P$21+AW7/AW$6*Mapping!$P$22+AX7/AX$6*Mapping!$P$23)/SUM(Mapping!$P$15:$P$23),"") | BR7: =IF(BA7="","",BA7+N(AS7)/10000)
A8: 2 | B8: 3rd Sem - A | AP8: =IF(COUNT(I8,T8,AE8)=0,"",AVERAGE(I8,T8,AE8)) | AQ8: =IF(COUNT(J8,U8,AF8)=0,"",AVERAGE(J8,U8,AF8)) | AR8: =IF(COUNT(K8,V8,AG8)=0,"",AVERAGE(K8,V8,AG8)) | AS8: =IF(COUNT(L8,W8,AH8)=0,"",AVERAGE(L8,W8,AH8)) | AT8: =IF(COUNT(M8,X8,AI8)=0,"",AVERAGE(M8,X8,AI8)) | AU8: =IF(COUNT(N8,Y8,AJ8)=0,"",AVERAGE(N8,Y8,AJ8)) | AV8: =IF(COUNT(O8,Z8,AK8)=0,"",AVERAGE(O8,Z8,AK8)) | AW8: =IF(COUNT(P8,AA8,AL8)=0,"",AVERAGE(P8,AA8,AL8)) | AX8: =IF(COUNT(Q8,AB8,AM8)=0,"",AVERAGE(Q8,AB8,AM8)) | AY8: =IF(OR($F8="",COUNT(R8,AC8,AN8)=0),"",AVERAGE(R8,AC8,AN8)) | AZ8: =IF(OR($G8="",$G8=$F8,COUNT(S8,AD8,AO8)=0),"",AVERAGE(S8,AD8,AO8)) | BA8: =IF(COUNT(AP8:AX8)=0,"",SUM(AP8:AX8)) | BB8: =IF(BA8="","",BA8/BA$6) | BC8: =IF(BR8="","",COUNTIF($BR$7:$BR$26,">"&BR8)+COUNTIF($BR$7:BR8,BR8)) | BD8: =IF(BC8="","",IF(BC8<=Mapping!$C$11,"Shortlisted","Not shortlisted")) | BE8: =IFERROR((AP8/AP$6*Mapping!$D$15+AQ8/AQ$6*Mapping!$D$16+AR8/AR$6*Mapping!$D$17+AS8/AS$6*Mapping!$D$18+AT8/AT$6*Mapping!$D$19+AU8/AU$6*Mapping!$D$20+AV8/AV$6*Mapping!$D$21+AW8/AW$6*Mapping!$D$22+AX8/AX$6*Mapping!$D$23)/SUM(Mapping!$D$15:$D$23),"") | BF8: =IFERROR((AP8/AP$6*Mapping!$E$15+AQ8/AQ$6*Mapping!$E$16+AR8/AR$6*Mapping!$E$17+AS8/AS$6*Mapping!$E$18+AT8/AT$6*Mapping!$E$19+AU8/AU$6*Mapping!$E$20+AV8/AV$6*Mapping!$E$21+AW8/AW$6*Mapping!$E$22+AX8/AX$6*Mapping!$E$23)/SUM(Mapping!$E$15:$E$23),"") | BG8: =IFERROR((AP8/AP$6*Mapping!$F$15+AQ8/AQ$6*Mapping!$F$16+AR8/AR$6*Mapping!$F$17+AS8/AS$6*Mapping!$F$18+AT8/AT$6*Mapping!$F$19+AU8/AU$6*Mapping!$F$20+AV8/AV$6*Mapping!$F$21+AW8/AW$6*Mapping!$F$22+AX8/AX$6*Mapping!$F$23)/SUM(Mapping!$F$15:$F$23),"") | BH8: =IFERROR((AP8/AP$6*Mapping!$G$15+AQ8/AQ$6*Mapping!$G$16+AR8/AR$6*Mapping!$G$17+AS8/AS$6*Mapping!$G$18+AT8/AT$6*Mapping!$G$19+AU8/AU$6*Mapping!$G$20+AV8/AV$6*Mapping!$G$21+AW8/AW$6*Mapping!$G$22+AX8/AX$6*Mapping!$G$23)/SUM(Mapping!$G$15:$G$23),"") | BI8: =IFERROR((AP8/AP$6*Mapping!$H$15+AQ8/AQ$6*Mapping!$H$16+AR8/AR$6*Mapping!$H$17+AS8/AS$6*Mapping!$H$18+AT8/AT$6*Mapping!$H$19+AU8/AU$6*Mapping!$H$20+AV8/AV$6*Mapping!$H$21+AW8/AW$6*Mapping!$H$22+AX8/AX$6*Mapping!$H$23)/SUM(Mapping!$H$15:$H$23),"") | BJ8: =IFERROR((AP8/AP$6*Mapping!$I$15+AQ8/AQ$6*Mapping!$I$16+AR8/AR$6*Mapping!$I$17+AS8/AS$6*Mapping!$I$18+AT8/AT$6*Mapping!$I$19+AU8/AU$6*Mapping!$I$20+AV8/AV$6*Mapping!$I$21+AW8/AW$6*Mapping!$I$22+AX8/AX$6*Mapping!$I$23)/SUM(Mapping!$I$15:$I$23),"") | BK8: =IFERROR((AP8/AP$6*Mapping!$J$15+AQ8/AQ$6*Mapping!$J$16+AR8/AR$6*Mapping!$J$17+AS8/AS$6*Mapping!$J$18+AT8/AT$6*Mapping!$J$19+AU8/AU$6*Mapping!$J$20+AV8/AV$6*Mapping!$J$21+AW8/AW$6*Mapping!$J$22+AX8/AX$6*Mapping!$J$23)/SUM(Mapping!$J$15:$J$23),"") | BL8: =IFERROR((AP8/AP$6*Mapping!$K$15+AQ8/AQ$6*Mapping!$K$16+AR8/AR$6*Mapping!$K$17+AS8/AS$6*Mapping!$K$18+AT8/AT$6*Mapping!$K$19+AU8/AU$6*Mapping!$K$20+AV8/AV$6*Mapping!$K$21+AW8/AW$6*Mapping!$K$22+AX8/AX$6*Mapping!$K$23)/SUM(Mapping!$K$15:$K$23),"") | BM8: =IFERROR((AP8/AP$6*Mapping!$L$15+AQ8/AQ$6*Mapping!$L$16+AR8/AR$6*Mapping!$L$17+AS8/AS$6*Mapping!$L$18+AT8/AT$6*Mapping!$L$19+AU8/AU$6*Mapping!$L$20+AV8/AV$6*Mapping!$L$21+AW8/AW$6*Mapping!$L$22+AX8/AX$6*Mapping!$L$23)/SUM(Mapping!$L$15:$L$23),"") | BN8: =IFERROR((AP8/AP$6*Mapping!$M$15+AQ8/AQ$6*Mapping!$M$16+AR8/AR$6*Mapping!$M$17+AS8/AS$6*Mapping!$M$18+AT8/AT$6*Mapping!$M$19+AU8/AU$6*Mapping!$M$20+AV8/AV$6*Mapping!$M$21+AW8/AW$6*Mapping!$M$22+AX8/AX$6*Mapping!$M$23)/SUM(Mapping!$M$15:$M$23),"") | BO8: =IFERROR((AP8/AP$6*Mapping!$N$15+AQ8/AQ$6*Mapping!$N$16+AR8/AR$6*Mapping!$N$17+AS8/AS$6*Mapping!$N$18+AT8/AT$6*Mapping!$N$19+AU8/AU$6*Mapping!$N$20+AV8/AV$6*Mapping!$N$21+AW8/AW$6*Mapping!$N$22+AX8/AX$6*Mapping!$N$23)/SUM(Mapping!$N$15:$N$23),"") | BP8: =IFERROR((AP8/AP$6*Mapping!$O$15+AQ8/AQ$6*Mapping!$O$16+AR8/AR$6*Mapping!$O$17+AS8/AS$6*Mapping!$O$18+AT8/AT$6*Mapping!$O$19+AU8/AU$6*Mapping!$O$20+AV8/AV$6*Mapping!$O$21+AW8/AW$6*Mapping!$O$22+AX8/AX$6*Mapping!$O$23)/SUM(Mapping!$O$15:$O$23),"") | BQ8: =IFERROR((AP8/AP$6*Mapping!$P$15+AQ8/AQ$6*Mapping!$P$16+AR8/AR$6*Mapping!$P$17+AS8/AS$6*Mapping!$P$18+AT8/AT$6*Mapping!$P$19+AU8/AU$6*Mapping!$P$20+AV8/AV$6*Mapping!$P$21+AW8/AW$6*Mapping!$P$22+AX8/AX$6*Mapping!$P$23)/SUM(Mapping!$P$15:$P$23),"") | BR8: =IF(BA8="","",BA8+N(AS8)/10000)
A9: 3 | B9: 3rd Sem - A | AP9: =IF(COUNT(I9,T9,AE9)=0,"",AVERAGE(I9,T9,AE9)) | AQ9: =IF(COUNT(J9,U9,AF9)=0,"",AVERAGE(J9,U9,AF9)) | AR9: =IF(COUNT(K9,V9,AG9)=0,"",AVERAGE(K9,V9,AG9)) | AS9: =IF(COUNT(L9,W9,AH9)=0,"",AVERAGE(L9,W9,AH9)) | AT9: =IF(COUNT(M9,X9,AI9)=0,"",AVERAGE(M9,X9,AI9)) | AU9: =IF(COUNT(N9,Y9,AJ9)=0,"",AVERAGE(N9,Y9,AJ9)) | AV9: =IF(COUNT(O9,Z9,AK9)=0,"",AVERAGE(O9,Z9,AK9)) | AW9: =IF(COUNT(P9,AA9,AL9)=0,"",AVERAGE(P9,AA9,AL9)) | AX9: =IF(COUNT(Q9,AB9,AM9)=0,"",AVERAGE(Q9,AB9,AM9)) | AY9: =IF(OR($F9="",COUNT(R9,AC9,AN9)=0),"",AVERAGE(R9,AC9,AN9)) | AZ9: =IF(OR($G9="",$G9=$F9,COUNT(S9,AD9,AO9)=0),"",AVERAGE(S9,AD9,AO9)) | BA9: =IF(COUNT(AP9:AX9)=0,"",SUM(AP9:AX9)) | BB9: =IF(BA9="","",BA9/BA$6) | BC9: =IF(BR9="","",COUNTIF($BR$7:$BR$26,">"&BR9)+COUNTIF($BR$7:BR9,BR9)) | BD9: =IF(BC9="","",IF(BC9<=Mapping!$C$11,"Shortlisted","Not shortlisted")) | BE9: =IFERROR((AP9/AP$6*Mapping!$D$15+AQ9/AQ$6*Mapping!$D$16+AR9/AR$6*Mapping!$D$17+AS9/AS$6*Mapping!$D$18+AT9/AT$6*Mapping!$D$19+AU9/AU$6*Mapping!$D$20+AV9/AV$6*Mapping!$D$21+AW9/AW$6*Mapping!$D$22+AX9/AX$6*Mapping!$D$23)/SUM(Mapping!$D$15:$D$23),"") | BF9: =IFERROR((AP9/AP$6*Mapping!$E$15+AQ9/AQ$6*Mapping!$E$16+AR9/AR$6*Mapping!$E$17+AS9/AS$6*Mapping!$E$18+AT9/AT$6*Mapping!$E$19+AU9/AU$6*Mapping!$E$20+AV9/AV$6*Mapping!$E$21+AW9/AW$6*Mapping!$E$22+AX9/AX$6*Mapping!$E$23)/SUM(Mapping!$E$15:$E$23),"") | BG9: =IFERROR((AP9/AP$6*Mapping!$F$15+AQ9/AQ$6*Mapping!$F$16+AR9/AR$6*Mapping!$F$17+AS9/AS$6*Mapping!$F$18+AT9/AT$6*Mapping!$F$19+AU9/AU$6*Mapping!$F$20+AV9/AV$6*Mapping!$F$21+AW9/AW$6*Mapping!$F$22+AX9/AX$6*Mapping!$F$23)/SUM(Mapping!$F$15:$F$23),"") | BH9: =IFERROR((AP9/AP$6*Mapping!$G$15+AQ9/AQ$6*Mapping!$G$16+AR9/AR$6*Mapping!$G$17+AS9/AS$6*Mapping!$G$18+AT9/AT$6*Mapping!$G$19+AU9/AU$6*Mapping!$G$20+AV9/AV$6*Mapping!$G$21+AW9/AW$6*Mapping!$G$22+AX9/AX$6*Mapping!$G$23)/SUM(Mapping!$G$15:$G$23),"") | BI9: =IFERROR((AP9/AP$6*Mapping!$H$15+AQ9/AQ$6*Mapping!$H$16+AR9/AR$6*Mapping!$H$17+AS9/AS$6*Mapping!$H$18+AT9/AT$6*Mapping!$H$19+AU9/AU$6*Mapping!$H$20+AV9/AV$6*Mapping!$H$21+AW9/AW$6*Mapping!$H$22+AX9/AX$6*Mapping!$H$23)/SUM(Mapping!$H$15:$H$23),"") | BJ9: =IFERROR((AP9/AP$6*Mapping!$I$15+AQ9/AQ$6*Mapping!$I$16+AR9/AR$6*Mapping!$I$17+AS9/AS$6*Mapping!$I$18+AT9/AT$6*Mapping!$I$19+AU9/AU$6*Mapping!$I$20+AV9/AV$6*Mapping!$I$21+AW9/AW$6*Mapping!$I$22+AX9/AX$6*Mapping!$I$23)/SUM(Mapping!$I$15:$I$23),"") | BK9: =IFERROR((AP9/AP$6*Mapping!$J$15+AQ9/AQ$6*Mapping!$J$16+AR9/AR$6*Mapping!$J$17+AS9/AS$6*Mapping!$J$18+AT9/AT$6*Mapping!$J$19+AU9/AU$6*Mapping!$J$20+AV9/AV$6*Mapping!$J$21+AW9/AW$6*Mapping!$J$22+AX9/AX$6*Mapping!$J$23)/SUM(Mapping!$J$15:$J$23),"") | BL9: =IFERROR((AP9/AP$6*Mapping!$K$15+AQ9/AQ$6*Mapping!$K$16+AR9/AR$6*Mapping!$K$17+AS9/AS$6*Mapping!$K$18+AT9/AT$6*Mapping!$K$19+AU9/AU$6*Mapping!$K$20+AV9/AV$6*Mapping!$K$21+AW9/AW$6*Mapping!$K$22+AX9/AX$6*Mapping!$K$23)/SUM(Mapping!$K$15:$K$23),"") | BM9: =IFERROR((AP9/AP$6*Mapping!$L$15+AQ9/AQ$6*Mapping!$L$16+AR9/AR$6*Mapping!$L$17+AS9/AS$6*Mapping!$L$18+AT9/AT$6*Mapping!$L$19+AU9/AU$6*Mapping!$L$20+AV9/AV$6*Mapping!$L$21+AW9/AW$6*Mapping!$L$22+AX9/AX$6*Mapping!$L$23)/SUM(Mapping!$L$15:$L$23),"") | BN9: =IFERROR((AP9/AP$6*Mapping!$M$15+AQ9/AQ$6*Mapping!$M$16+AR9/AR$6*Mapping!$M$17+AS9/AS$6*Mapping!$M$18+AT9/AT$6*Mapping!$M$19+AU9/AU$6*Mapping!$M$20+AV9/AV$6*Mapping!$M$21+AW9/AW$6*Mapping!$M$22+AX9/AX$6*Mapping!$M$23)/SUM(Mapping!$M$15:$M$23),"") | BO9: =IFERROR((AP9/AP$6*Mapping!$N$15+AQ9/AQ$6*Mapping!$N$16+AR9/AR$6*Mapping!$N$17+AS9/AS$6*Mapping!$N$18+AT9/AT$6*Mapping!$N$19+AU9/AU$6*Mapping!$N$20+AV9/AV$6*Mapping!$N$21+AW9/AW$6*Mapping!$N$22+AX9/AX$6*Mapping!$N$23)/SUM(Mapping!$N$15:$N$23),"") | BP9: =IFERROR((AP9/AP$6*Mapping!$O$15+AQ9/AQ$6*Mapping!$O$16+AR9/AR$6*Mapping!$O$17+AS9/AS$6*Mapping!$O$18+AT9/AT$6*Mapping!$O$19+AU9/AU$6*Mapping!$O$20+AV9/AV$6*Mapping!$O$21+AW9/AW$6*Mapping!$O$22+AX9/AX$6*Mapping!$O$23)/SUM(Mapping!$O$15:$O$23),"") | BQ9: =IFERROR((AP9/AP$6*Mapping!$P$15+AQ9/AQ$6*Mapping!$P$16+AR9/AR$6*Mapping!$P$17+AS9/AS$6*Mapping!$P$18+AT9/AT$6*Mapping!$P$19+AU9/AU$6*Mapping!$P$20+AV9/AV$6*Mapping!$P$21+AW9/AW$6*Mapping!$P$22+AX9/AX$6*Mapping!$P$23)/SUM(Mapping!$P$15:$P$23),"") | BR9: =IF(BA9="","",BA9+N(AS9)/10000)
A10: 4 | B10: 3rd Sem - A | AP10: =IF(COUNT(I10,T10,AE10)=0,"",AVERAGE(I10,T10,AE10)) | AQ10: =IF(COUNT(J10,U10,AF10)=0,"",AVERAGE(J10,U10,AF10)) | AR10: =IF(COUNT(K10,V10,AG10)=0,"",AVERAGE(K10,V10,AG10)) | AS10: =IF(COUNT(L10,W10,AH10)=0,"",AVERAGE(L10,W10,AH10)) | AT10: =IF(COUNT(M10,X10,AI10)=0,"",AVERAGE(M10,X10,AI10)) | AU10: =IF(COUNT(N10,Y10,AJ10)=0,"",AVERAGE(N10,Y10,AJ10)) | AV10: =IF(COUNT(O10,Z10,AK10)=0,"",AVERAGE(O10,Z10,AK10)) | AW10: =IF(COUNT(P10,AA10,AL10)=0,"",AVERAGE(P10,AA10,AL10)) | AX10: =IF(COUNT(Q10,AB10,AM10)=0,"",AVERAGE(Q10,AB10,AM10)) | AY10: =IF(OR($F10="",COUNT(R10,AC10,AN10)=0),"",AVERAGE(R10,AC10,AN10)) | AZ10: =IF(OR($G10="",$G10=$F10,COUNT(S10,AD10,AO10)=0),"",AVERAGE(S10,AD10,AO10)) | BA10: =IF(COUNT(AP10:AX10)=0,"",SUM(AP10:AX10)) | BB10: =IF(BA10="","",BA10/BA$6) | BC10: =IF(BR10="","",COUNTIF($BR$7:$BR$26,">"&BR10)+COUNTIF($BR$7:BR10,BR10)) | BD10: =IF(BC10="","",IF(BC10<=Mapping!$C$11,"Shortlisted","Not shortlisted")) | BE10: =IFERROR((AP10/AP$6*Mapping!$D$15+AQ10/AQ$6*Mapping!$D$16+AR10/AR$6*Mapping!$D$17+AS10/AS$6*Mapping!$D$18+AT10/AT$6*Mapping!$D$19+AU10/AU$6*Mapping!$D$20+AV10/AV$6*Mapping!$D$21+AW10/AW$6*Mapping!$D$22+AX10/AX$6*Mapping!$D$23)/SUM(Mapping!$D$15:$D$23),"") | BF10: =IFERROR((AP10/AP$6*Mapping!$E$15+AQ10/AQ$6*Mapping!$E$16+AR10/AR$6*Mapping!$E$17+AS10/AS$6*Mapping!$E$18+AT10/AT$6*Mapping!$E$19+AU10/AU$6*Mapping!$E$20+AV10/AV$6*Mapping!$E$21+AW10/AW$6*Mapping!$E$22+AX10/AX$6*Mapping!$E$23)/SUM(Mapping!$E$15:$E$23),"") | BG10: =IFERROR((AP10/AP$6*Mapping!$F$15+AQ10/AQ$6*Mapping!$F$16+AR10/AR$6*Mapping!$F$17+AS10/AS$6*Mapping!$F$18+AT10/AT$6*Mapping!$F$19+AU10/AU$6*Mapping!$F$20+AV10/AV$6*Mapping!$F$21+AW10/AW$6*Mapping!$F$22+AX10/AX$6*Mapping!$F$23)/SUM(Mapping!$F$15:$F$23),"") | BH10: =IFERROR((AP10/AP$6*Mapping!$G$15+AQ10/AQ$6*Mapping!$G$16+AR10/AR$6*Mapping!$G$17+AS10/AS$6*Mapping!$G$18+AT10/AT$6*Mapping!$G$19+AU10/AU$6*Mapping!$G$20+AV10/AV$6*Mapping!$G$21+AW10/AW$6*Mapping!$G$22+AX10/AX$6*Mapping!$G$23)/SUM(Mapping!$G$15:$G$23),"") | BI10: =IFERROR((AP10/AP$6*Mapping!$H$15+AQ10/AQ$6*Mapping!$H$16+AR10/AR$6*Mapping!$H$17+AS10/AS$6*Mapping!$H$18+AT10/AT$6*Mapping!$H$19+AU10/AU$6*Mapping!$H$20+AV10/AV$6*Mapping!$H$21+AW10/AW$6*Mapping!$H$22+AX10/AX$6*Mapping!$H$23)/SUM(Mapping!$H$15:$H$23),"") | BJ10: =IFERROR((AP10/AP$6*Mapping!$I$15+AQ10/AQ$6*Mapping!$I$16+AR10/AR$6*Mapping!$I$17+AS10/AS$6*Mapping!$I$18+AT10/AT$6*Mapping!$I$19+AU10/AU$6*Mapping!$I$20+AV10/AV$6*Mapping!$I$21+AW10/AW$6*Mapping!$I$22+AX10/AX$6*Mapping!$I$23)/SUM(Mapping!$I$15:$I$23),"") | BK10: =IFERROR((AP10/AP$6*Mapping!$J$15+AQ10/AQ$6*Mapping!$J$16+AR10/AR$6*Mapping!$J$17+AS10/AS$6*Mapping!$J$18+AT10/AT$6*Mapping!$J$19+AU10/AU$6*Mapping!$J$20+AV10/AV$6*Mapping!$J$21+AW10/AW$6*Mapping!$J$22+AX10/AX$6*Mapping!$J$23)/SUM(Mapping!$J$15:$J$23),"") | BL10: =IFERROR((AP10/AP$6*Mapping!$K$15+AQ10/AQ$6*Mapping!$K$16+AR10/AR$6*Mapping!$K$17+AS10/AS$6*Mapping!$K$18+AT10/AT$6*Mapping!$K$19+AU10/AU$6*Mapping!$K$20+AV10/AV$6*Mapping!$K$21+AW10/AW$6*Mapping!$K$22+AX10/AX$6*Mapping!$K$23)/SUM(Mapping!$K$15:$K$23),"") | BM10: =IFERROR((AP10/AP$6*Mapping!$L$15+AQ10/AQ$6*Mapping!$L$16+AR10/AR$6*Mapping!$L$17+AS10/AS$6*Mapping!$L$18+AT10/AT$6*Mapping!$L$19+AU10/AU$6*Mapping!$L$20+AV10/AV$6*Mapping!$L$21+AW10/AW$6*Mapping!$L$22+AX10/AX$6*Mapping!$L$23)/SUM(Mapping!$L$15:$L$23),"") | BN10: =IFERROR((AP10/AP$6*Mapping!$M$15+AQ10/AQ$6*Mapping!$M$16+AR10/AR$6*Mapping!$M$17+AS10/AS$6*Mapping!$M$18+AT10/AT$6*Mapping!$M$19+AU10/AU$6*Mapping!$M$20+AV10/AV$6*Mapping!$M$21+AW10/AW$6*Mapping!$M$22+AX10/AX$6*Mapping!$M$23)/SUM(Mapping!$M$15:$M$23),"") | BO10: =IFERROR((AP10/AP$6*Mapping!$N$15+AQ10/AQ$6*Mapping!$N$16+AR10/AR$6*Mapping!$N$17+AS10/AS$6*Mapping!$N$18+AT10/AT$6*Mapping!$N$19+AU10/AU$6*Mapping!$N$20+AV10/AV$6*Mapping!$N$21+AW10/AW$6*Mapping!$N$22+AX10/AX$6*Mapping!$N$23)/SUM(Mapping!$N$15:$N$23),"") | BP10: =IFERROR((AP10/AP$6*Mapping!$O$15+AQ10/AQ$6*Mapping!$O$16+AR10/AR$6*Mapping!$O$17+AS10/AS$6*Mapping!$O$18+AT10/AT$6*Mapping!$O$19+AU10/AU$6*Mapping!$O$20+AV10/AV$6*Mapping!$O$21+AW10/AW$6*Mapping!$O$22+AX10/AX$6*Mapping!$O$23)/SUM(Mapping!$O$15:$O$23),"") | BQ10: =IFERROR((AP10/AP$6*Mapping!$P$15+AQ10/AQ$6*Mapping!$P$16+AR10/AR$6*Mapping!$P$17+AS10/AS$6*Mapping!$P$18+AT10/AT$6*Mapping!$P$19+AU10/AU$6*Mapping!$P$20+AV10/AV$6*Mapping!$P$21+AW10/AW$6*Mapping!$P$22+AX10/AX$6*Mapping!$P$23)/SUM(Mapping!$P$15:$P$23),"") | BR10: =IF(BA10="","",BA10+N(AS10)/10000)
A11: 5 | B11: 3rd Sem - A | AP11: =IF(COUNT(I11,T11,AE11)=0,"",AVERAGE(I11,T11,AE11)) | AQ11: =IF(COUNT(J11,U11,AF11)=0,"",AVERAGE(J11,U11,AF11)) | AR11: =IF(COUNT(K11,V11,AG11)=0,"",AVERAGE(K11,V11,AG11)) | AS11: =IF(COUNT(L11,W11,AH11)=0,"",AVERAGE(L11,W11,AH11)) | AT11: =IF(COUNT(M11,X11,AI11)=0,"",AVERAGE(M11,X11,AI11)) | AU11: =IF(COUNT(N11,Y11,AJ11)=0,"",AVERAGE(N11,Y11,AJ11)) | AV11: =IF(COUNT(O11,Z11,AK11)=0,"",AVERAGE(O11,Z11,AK11)) | AW11: =IF(COUNT(P11,AA11,AL11)=0,"",AVERAGE(P11,AA11,AL11)) | AX11: =IF(COUNT(Q11,AB11,AM11)=0,"",AVERAGE(Q11,AB11,AM11)) | AY11: =IF(OR($F11="",COUNT(R11,AC11,AN11)=0),"",AVERAGE(R11,AC11,AN11)) | AZ11: =IF(OR($G11="",$G11=$F11,COUNT(S11,AD11,AO11)=0),"",AVERAGE(S11,AD11,AO11)) | BA11: =IF(COUNT(AP11:AX11)=0,"",SUM(AP11:AX11)) | BB11: =IF(BA11="","",BA11/BA$6) | BC11: =IF(BR11="","",COUNTIF($BR$7:$BR$26,">"&BR11)+COUNTIF($BR$7:BR11,BR11)) | BD11: =IF(BC11="","",IF(BC11<=Mapping!$C$11,"Shortlisted","Not shortlisted")) | BE11: =IFERROR((AP11/AP$6*Mapping!$D$15+AQ11/AQ$6*Mapping!$D$16+AR11/AR$6*Mapping!$D$17+AS11/AS$6*Mapping!$D$18+AT11/AT$6*Mapping!$D$19+AU11/AU$6*Mapping!$D$20+AV11/AV$6*Mapping!$D$21+AW11/AW$6*Mapping!$D$22+AX11/AX$6*Mapping!$D$23)/SUM(Mapping!$D$15:$D$23),"") | BF11: =IFERROR((AP11/AP$6*Mapping!$E$15+AQ11/AQ$6*Mapping!$E$16+AR11/AR$6*Mapping!$E$17+AS11/AS$6*Mapping!$E$18+AT11/AT$6*Mapping!$E$19+AU11/AU$6*Mapping!$E$20+AV11/AV$6*Mapping!$E$21+AW11/AW$6*Mapping!$E$22+AX11/AX$6*Mapping!$E$23)/SUM(Mapping!$E$15:$E$23),"") | BG11: =IFERROR((AP11/AP$6*Mapping!$F$15+AQ11/AQ$6*Mapping!$F$16+AR11/AR$6*Mapping!$F$17+AS11/AS$6*Mapping!$F$18+AT11/AT$6*Mapping!$F$19+AU11/AU$6*Mapping!$F$20+AV11/AV$6*Mapping!$F$21+AW11/AW$6*Mapping!$F$22+AX11/AX$6*Mapping!$F$23)/SUM(Mapping!$F$15:$F$23),"") | BH11: =IFERROR((AP11/AP$6*Mapping!$G$15+AQ11/AQ$6*Mapping!$G$16+AR11/AR$6*Mapping!$G$17+AS11/AS$6*Mapping!$G$18+AT11/AT$6*Mapping!$G$19+AU11/AU$6*Mapping!$G$20+AV11/AV$6*Mapping!$G$21+AW11/AW$6*Mapping!$G$22+AX11/AX$6*Mapping!$G$23)/SUM(Mapping!$G$15:$G$23),"") | BI11: =IFERROR((AP11/AP$6*Mapping!$H$15+AQ11/AQ$6*Mapping!$H$16+AR11/AR$6*Mapping!$H$17+AS11/AS$6*Mapping!$H$18+AT11/AT$6*Mapping!$H$19+AU11/AU$6*Mapping!$H$20+AV11/AV$6*Mapping!$H$21+AW11/AW$6*Mapping!$H$22+AX11/AX$6*Mapping!$H$23)/SUM(Mapping!$H$15:$H$23),"") | BJ11: =IFERROR((AP11/AP$6*Mapping!$I$15+AQ11/AQ$6*Mapping!$I$16+AR11/AR$6*Mapping!$I$17+AS11/AS$6*Mapping!$I$18+AT11/AT$6*Mapping!$I$19+AU11/AU$6*Mapping!$I$20+AV11/AV$6*Mapping!$I$21+AW11/AW$6*Mapping!$I$22+AX11/AX$6*Mapping!$I$23)/SUM(Mapping!$I$15:$I$23),"") | BK11: =IFERROR((AP11/AP$6*Mapping!$J$15+AQ11/AQ$6*Mapping!$J$16+AR11/AR$6*Mapping!$J$17+AS11/AS$6*Mapping!$J$18+AT11/AT$6*Mapping!$J$19+AU11/AU$6*Mapping!$J$20+AV11/AV$6*Mapping!$J$21+AW11/AW$6*Mapping!$J$22+AX11/AX$6*Mapping!$J$23)/SUM(Mapping!$J$15:$J$23),"") | BL11: =IFERROR((AP11/AP$6*Mapping!$K$15+AQ11/AQ$6*Mapping!$K$16+AR11/AR$6*Mapping!$K$17+AS11/AS$6*Mapping!$K$18+AT11/AT$6*Mapping!$K$19+AU11/AU$6*Mapping!$K$20+AV11/AV$6*Mapping!$K$21+AW11/AW$6*Mapping!$K$22+AX11/AX$6*Mapping!$K$23)/SUM(Mapping!$K$15:$K$23),"") | BM11: =IFERROR((AP11/AP$6*Mapping!$L$15+AQ11/AQ$6*Mapping!$L$16+AR11/AR$6*Mapping!$L$17+AS11/AS$6*Mapping!$L$18+AT11/AT$6*Mapping!$L$19+AU11/AU$6*Mapping!$L$20+AV11/AV$6*Mapping!$L$21+AW11/AW$6*Mapping!$L$22+AX11/AX$6*Mapping!$L$23)/SUM(Mapping!$L$15:$L$23),"") | BN11: =IFERROR((AP11/AP$6*Mapping!$M$15+AQ11/AQ$6*Mapping!$M$16+AR11/AR$6*Mapping!$M$17+AS11/AS$6*Mapping!$M$18+AT11/AT$6*Mapping!$M$19+AU11/AU$6*Mapping!$M$20+AV11/AV$6*Mapping!$M$21+AW11/AW$6*Mapping!$M$22+AX11/AX$6*Mapping!$M$23)/SUM(Mapping!$M$15:$M$23),"") | BO11: =IFERROR((AP11/AP$6*Mapping!$N$15+AQ11/AQ$6*Mapping!$N$16+AR11/AR$6*Mapping!$N$17+AS11/AS$6*Mapping!$N$18+AT11/AT$6*Mapping!$N$19+AU11/AU$6*Mapping!$N$20+AV11/AV$6*Mapping!$N$21+AW11/AW$6*Mapping!$N$22+AX11/AX$6*Mapping!$N$23)/SUM(Mapping!$N$15:$N$23),"") | BP11: =IFERROR((AP11/AP$6*Mapping!$O$15+AQ11/AQ$6*Mapping!$O$16+AR11/AR$6*Mapping!$O$17+AS11/AS$6*Mapping!$O$18+AT11/AT$6*Mapping!$O$19+AU11/AU$6*Mapping!$O$20+AV11/AV$6*Mapping!$O$21+AW11/AW$6*Mapping!$O$22+AX11/AX$6*Mapping!$O$23)/SUM(Mapping!$O$15:$O$23),"") | BQ11: =IFERROR((AP11/AP$6*Mapping!$P$15+AQ11/AQ$6*Mapping!$P$16+AR11/AR$6*Mapping!$P$17+AS11/AS$6*Mapping!$P$18+AT11/AT$6*Mapping!$P$19+AU11/AU$6*Mapping!$P$20+AV11/AV$6*Mapping!$P$21+AW11/AW$6*Mapping!$P$22+AX11/AX$6*Mapping!$P$23)/SUM(Mapping!$P$15:$P$23),"") | BR11: =IF(BA11="","",BA11+N(AS11)/10000)
